<?xml version="1.0" encoding="UTF-8"?>
<mujoco model="Leap Hand">
  <compiler angle="radian"/>
  <option timestep="0.00002" integrator="Euler" cone="elliptic" solver="PGS" noslip_iterations="10">
    <!-- <flag contact="disable" gravity="disable"/> -->
    <flag gravity="enable"/>
  </option>

  <asset>
    <mesh name="palm_lower" file="palm_lower.stl"/>
    <mesh name="mcp_joint" file="mcp_joint.stl"/>
    <mesh name="pip" file="pip.stl"/>
    <mesh name="dip" file="dip.stl"/>
    <mesh name="fingertip" file="fingertip.stl"/>
    <mesh name="thumb_dip" file="thumb_dip.stl"/>
    <mesh name="thumb_fingertip" file="thumb_fingertip.stl"/>
    <mesh name="thumb_pip" file="thumb_pip.stl"/>
    <texture name="grid" type="2d" builtin="checker" width="512" height="512" rgb1=".1 .2 .3" rgb2=".2 .3 .4"/>
    <material name="grid" texture="grid" texrepeat="1 1" texuniform="true" reflectance="0"/>
    <material name="box" rgba="0.2 0.6 0.9 1" specular="0.5" reflectance="0.1"/>
    <material name="soft_material" rgba="0.2 0.8 0.2 1" specular="0.1" reflectance="0.1" shininess="0.1"/>

  </asset>



  <worldbody>

    <light name="top" pos="0 0 1"/>
    <geom type="plane" pos="0 0 0" size="3 3 .01" material="grid"/>
    <camera name="closeup" mode="fixed" pos="-0.02 1 0.025" xyaxes="-1 0 0 0 0 1"/>
    <camera name="top" mode="fixed" pos="0 0 0.8" xyaxes="1 0 0 0 1 0"/>
    
    <body name="cube_small" pos="-0.023 0.005 0.126">
    <inertial pos="0 0 0" mass="0.001" diaginertia="0.001 0.001 0.001"/>
    <geom name="cube_small" type="box" size="0.026 0.055 0.026" material="box" condim="4" friction="1.2 0.5 0.0001"/>
    <site name="contact_index1" pos="0.026 0 -0.005" quat="0.7071 0 0.7071 0"/>
    <site name="contact_thumb1" pos="-0.026 0 -0.005" quat="0.7071 -0.7071 0 0"/>
    <site name="contact_index2" pos="0.013 0 0" quat="0.7071 0 0.7071 0"/>
    <site name="contact_thumb2" pos="-0.013 0 0" quat="0.7071 -0.7071 0 0"/>
    <site name="contact_push1" pos="-0.026 0.09 -0.015" quat="0.7071 -0.7071 0 0"/>
    <site name="contact_push2" pos="-0.026 0.042 -0.015" quat="0.7071 -0.7071 0 0"/>
    <site name="contact_grip1" pos="0 -0.0505 -0.026" quat="1 0 0 0"/>
    <site name="contact_grip2" pos="0 -0.005 -0.026" quat="1 0 0 0"/>
    <site name="contact_grip3" pos="0 -0.0505 -0.015" quat="1 0 0 0"/>
    <site name="contact_grip4" pos="0 -0.005 -0.015" quat="1 0 0 0"/>
    <joint name="box_small" type="free"/>
        </body>

    <body name="cube_big" pos="-0.022 0.005 0.05">
    <inertial pos="0 0 0" mass="0.01" diaginertia="0.001 0.001 0.001"/>
    <geom name="cube_big" type="box" size="0.035 0.015 0.05" material="box" condim="4" friction="1.2 0.5 0.0001"/>
    <site name="contact_index0_big" pos="0.049 0 0.04" quat="0.7071 0 0.7071 0"/>
    <site name="contact_thumb0_big" pos="-0.035 0 0.04" quat="0.7071 -0.7071 0 0"/>
    <site name="contact_index1_big" pos="0.035 0 0.04" quat="0.7071 0 0.7071 0"/>
    <site name="contact_thumb1_big" pos="-0.035 0 0.04" quat="0.7071 -0.7071 0 0"/>
    <site name="contact_index2_big" pos="0.035 0 0.04" quat="0.7071 0 0.7071 0"/>
    <site name="contact_thumb2_big" pos="-0.035 0 0.04" quat="0.7071 -0.7071 0 0"/>
    <joint name="box_big" type="free"/>
        </body>

    

    <body name="arm" pos="-0.5 0 0.258">
      <geom type="box" size="0.01 0.01 0.01" material="box"/>
      <joint name="palm_slide" type="slide" range="-0.05 0.5" damping="25"/>

    <body name="wrist" pos="0.3 0 0">
      <geom type="cylinder" size="0.01 0.05" euler="0 1.5708 0" material="box"/>
      <joint name="wrist" type="hinge" axis="1 0 0" range="0 3.1415" damping="10"/>
      
    <body name="palm" pos="0.2 0 0">
    <geom name="palm" pos="-0.0200952 0.0257578 -0.0347224" type="mesh" rgba="0.603922 0.14902 0.14902 1" mesh="palm_lower"  condim="4" solimp="0.99 0.99 0.01" solref="0.01 1" friction="2 0.5 0.001"/>
    
    <body name="mcp_joint" pos="-0.00709525 0.0230578 -0.0187224" quat="0.5 0.5 0.5 -0.5">
     <!-- <inertial pos="0 0 0" quat="0.388585 0.626468 -0.324549 0.592628" mass="0.044" diaginertia="1.47756e-05 1.31982e-05 6.0802e-06"/> -->
      <joint name="1" pos="0 0 0" axis="0 0 -1" range="-0.314 2.23" damping="0.1"/>
      <geom pos="0.0084069 0.00776624 0.0146574" quat="1 0 0 0" type="mesh" rgba="0.866667 0.866667 0.0509804 1" mesh="mcp_joint" condim="4" solimp="0.99 0.99 0.01" solref="0.01 1"/>
      <body name="pip" pos="-0.0122 0.0381 0.0145" quat="0.5 -0.5 -0.5 0.5">
        <!-- <inertial pos="0 0 0" quat="0.709913 0.704273 -0.000363156 0.00475427" mass="0.032" diaginertia="4.7981e-06 4.23406e-06 2.86184e-06"/> -->
        <joint name="0" pos="0 0 0" axis="0 0 -1" range="-1.047 1.047" damping="0.1"/>
        <geom pos="0.00964336 0.0003 0.000784034" quat="0.5 -0.5 -0.5 -0.5" type="mesh" rgba="0.74902 0.74902 0.74902 1" mesh="pip" condim="4" solimp="0.99 0.99 0.01" solref="0.01 1"/>
        <body name="dip" pos="0.015 0.0143 -0.013" quat="0.5 0.5 -0.5 0.5">
          <!-- <inertial pos="0 0 0" quat="-0.252689 0.659216 0.238844 0.666735" mass="0.037" diaginertia="6.68256e-06 6.24841e-06 5.02002e-06"/> -->
          <joint name="2" pos="0 0 0" axis="0 0 -1" range="-0.506 1.885" damping="0.1"/>
          <geom pos="0.0211334 -0.00843212 0.00978509" quat="0 -1 0 0" type="mesh" rgba="0.866667 0.866667 0.0509804 1" mesh="dip" condim="4" solimp="0.99 0.99 0.01" solref="0.01 1"/>
          <body name="fingertip" pos="-4.08806e-09 -0.0361 0.0002">
            <!-- <inertial pos="0 0 0" quat="0.706755 0.706755 0.0223155 0.0223155" mass="0.016" diaginertia="3.37527e-06 2.863e-06 1.54873e-06"/> -->
            <joint name="3" pos="0 0 0" axis="0 0 -1" range="-0.366 2.042" damping="0.1"/>
            <!-- <geom pos="0.0132864 -0.00611424 0.0145" quat="0 1 0 0" type="mesh" rgba="0.866667 0.866667 0.0509804 1" mesh="fingertip" solimp="0.6 0.8 0.01 0.02 0.001" solref="0.02 0.8" margin="0.005" material="soft_material"/> -->
            <geom pos="0.0132864 -0.00611424 0.0145" quat="0 1 0 0" type="mesh" rgba="0.866667 0.866667 0.0509804 1" mesh="fingertip" condim="4" solimp="0.99 0.99 0.01" solref="0.01 1"/>
          </body>
        </body>
      </body>
    </body>
  

    <body name="mcp_joint_2" pos="-0.00709525 -0.0223922 -0.0187224" quat="0.5 0.5 0.5 -0.5">
      <joint name="5" pos="0 0 0" axis="0 0 -1" range="-0.314 1.52" damping="0.1" />
      <geom pos="0.0084069 0.00776624 0.0146574" quat="1 0 0 0" type="mesh" rgba="0.866667 0.866667 0.0509804 1" mesh="mcp_joint" condim="4" solimp="0.99 0.99 0.01" solref="0.01 1"/>
      <body name="pip_2" pos="-0.0122 0.0381 0.0145" quat="0.5 -0.5 -0.5 0.5">
        <joint name="4" pos="0 0 0" axis="0 0 -1" range="-1.047 1.047" damping="0.1" />
        <geom pos="0.00964336 0.0003 0.000784034" quat="0.5 -0.5 -0.5 -0.5" type="mesh" rgba="0.74902 0.74902 0.74902 1" mesh="pip" condim="4" solimp="0.99 0.99 0.01" solref="0.01 1"/>
        <body name="dip_2" pos="0.015 0.0143 -0.013" quat="0.5 0.5 -0.5 0.5">
          <joint name="6" pos="0 0 0" axis="0 0 -1" range="-0.506 1.885" damping="0.1"/>
          <geom pos="0.0211334 -0.00843212 0.00978509" quat="0 -1 0 0" type="mesh" rgba="0.866667 0.866667 0.0509804 1" mesh="dip" condim="4" solimp="0.99 0.99 0.01" solref="0.01 1"/>
          <body name="fingertip_2" pos="0 -0.0361 0.0002">
            <joint name="7" pos="0 0 0" axis="0 0 -1" range="-0.366 2.042" damping="0.1"/>
            <geom pos="0.0132864 -0.00611424 0.0145" quat="0 1 0 0" type="mesh" rgba="0.866667 0.866667 0.0509804 1" mesh="fingertip" condim="4" solimp="0.99 0.99 0.01" solref="0.01 1"/>
          </body>
        </body>
      </body>
    </body>

    <body name="mcp_joint_3" pos="-0.00709525 -0.0678422 -0.0187224" quat="0.5 0.5 0.5 -0.5">
      <joint name="9" pos="0 0 0" axis="0 0 -1" range="-0.314 1.52" damping="0.1"/>
      <geom pos="0.0084069 0.00776624 0.0146574" quat="1 0 0 0" type="mesh" rgba="0.866667 0.866667 0.0509804 1" mesh="mcp_joint" condim="4" solimp="0.99 0.99 0.01" solref="0.01 1"/>
      <body name="pip_3" pos="-0.0122 0.0381 0.0145" quat="0.5 -0.5 -0.5 0.5">
        <joint name="8" pos="0 0 0" axis="0 0 -1" range="-1.047 1.047" damping="0.1"/>
        <geom pos="0.00964336 0.0003 0.000784034" quat="0.5 -0.5 -0.5 -0.5" type="mesh" rgba="0.74902 0.74902 0.74902 1" mesh="pip" condim="4" solimp="0.99 0.99 0.01" solref="0.01 1"/>
        <body name="dip_3" pos="0.015 0.0143 -0.013" quat="0.5 0.5 -0.5 0.5">
          <joint name="10" pos="0 0 0" axis="0 0 -1" range="-0.506 1.885" damping="0.1"/>
          <geom pos="0.0211334 -0.00843212 0.00978509" quat="0 -1 0 0" type="mesh" rgba="0.866667 0.866667 0.0509804 1" mesh="dip" condim="4" solimp="0.99 0.99 0.01" solref="0.01 1"/>
          <body name="fingertip_3" pos="0 -0.0361 0.0002">
            <joint name="11" pos="0 0 0" axis="0 0 -1" range="-0.366 2.042" damping="0.1"/>
            <geom pos="0.0132864 -0.00611424 0.0145" quat="0 1 0 0" type="mesh" rgba="0.866667 0.866667 0.0509804 1" mesh="fingertip" condim="4" solimp="0.99 0.99 0.01" solref="0.01 1"/>
          </body>
        </body>
      </body>
    </body>

    <body name="pip_4" pos="-0.0693952 -0.00124224 -0.0216224" quat="0.707107 0 0.707107 0">
      <!-- <inertial pos="0 0 0" quat="0.709913 0.704273 -0.000363156 0.00475427" mass="0.032" diaginertia="4.7981e-06 4.23406e-06 2.86184e-06"/> -->
      <joint name="12" pos="0 0 0" axis="0 0 -1" range="-0.349 2.094" damping="0.1"/>
      <geom pos="-0.00535664 0.0003 0.000784034" quat="0.5 -0.5 -0.5 -0.5" type="mesh" rgba="0.74902 0.74902 0.74902 1" mesh="pip"/>
      <body name="thumb_pip_4" pos="0 0.0143 -0.013" quat="0.5 0.5 -0.5 0.5">
        <!-- <inertial pos="0 0 0" mass="0.003" diaginertia="5.93e-07 5.49e-07 2.24e-07"/> -->
        <joint name="13" pos="0 0 0" axis="0 0 -1" range="-0.47 2.443" damping="0.1"/>
        <geom pos="0.0119619 0 -0.0158526" quat="0.707107 0.707107 0 0" type="mesh" rgba="0.866667 0.866667 0.0509804 1" mesh="thumb_pip"/>
        <body name="thumb_dip_4" pos="0 0.0145 -0.017" quat="0.707107 -0.707107 0 0">
          <!-- <inertial pos="0 0 0" quat="0.708624 0.704906 0.00637342 0.0303153" mass="0.038" diaginertia="8.48742e-06 7.67823e-06 3.82835e-06"/> -->
          <joint name="14" pos="0 0 0" axis="0 0 -1" range="-1.20 1.90" damping="0.1"/>
          <geom pos="0.0439687 0.057953 -0.00862868" quat="1 0 0 0" type="mesh" rgba="0.866667 0.866667 0.0509804 1" mesh="thumb_dip"/>
          <body name="thumb_fingertip_4" pos="0 0.0466 0.0002" quat="0 0 0 1">
            <!-- <inertial pos="0 0 0" quat="0.704307 0.709299 0.006848 -0.0282727" mass="0.049" diaginertia="2.03882e-05 1.98443e-05 4.32049e-06"/> -->
            <joint name="15" pos="0 0 0" axis="0 0 -1" range="-1.34 1.88" damping="0.1"/>
            <geom pos="0.0625595 0.0784597 0.0489929" type="mesh" rgba="0.603922 0.14902 0.14902 1" mesh="thumb_fingertip" condim="4" solimp="0.99 0.99 0.01" solref="0.01 1"/>
          </body>
        </body>
      </body>
    </body>
    </body>
    </body>
    </body>
    
  </worldbody>

<actuator>
    <motor name="palm_slide" joint="palm_slide"/>
    <motor name="wrist" joint="wrist"/>
    <motor name="motor_1" joint="1"/>
    <motor name="motor_0" joint="0"/>
    <motor name="motor_2" joint="2"/>
    <motor name="motor_3" joint="3"/>
    <motor name="motor_5" joint="5"/>
    <motor name="motor_4" joint="4"/>
    <motor name="motor_6" joint="6"/>
    <motor name="motor_7" joint="7"/>
    <motor name="motor_9" joint="9"/>
    <motor name="motor_8" joint="8"/>
    <motor name="motor_10" joint="10"/>
    <motor name="motor_11" joint="11"/>
    <motor name="motor_12" joint="12"/>
    <motor name="motor_13" joint="13"/>
    <motor name="motor_14" joint="14"/>
    <motor name="motor_15" joint="15"/>
  </actuator>

<contact>
<exclude body1="palm" body2="mcp_joint"/>
<exclude body1="palm" body2="mcp_joint_2"/>
<exclude body1="palm" body2="mcp_joint_3"/>
<exclude body1="palm" body2="pip_4"/>
</contact>

</mujoco>
